Workbook
Name ACTION: #REF!
Name ACTION: #REF!

Sheet Cover
B2: TEST REPORT DOCUMENT
A4: Project Name | B4: CampusStay FPT - Dormitory Registration and Room-Scheduling Management System | E4: Creator | F4: Võ Minh Luân
A5: Project Code | B5: FA26SE260 | E5: Issue Date | F5: 30/10/2026
A6: Document Code | B6: FA26SE260_TestReport_v1.0 | E6: Version | F6: 1
A9: Record of change
A10: Effective Date | B10: Version | C10: Change Item | D10: *A,D,M | E10: Change description | F10: Reference
A11: 30/10/2026 | B11: 1.0 | C11: Whole document | D11: A | E11: First version for Review 2: test cases of the mandatory features, main workflows, state transitions and NFRs; round 1 = automated run | F11: Report 3 (SRS), Report 4 (SDD), Report 5, docs/backend/04_Test_Catalog.md

Sheet Test Cases
D1: TEST CASE LIST
B3: Project Name | D3: =#REF! -> #REF!
B4: Project Code | D4: =#REF! -> #REF!
B5: Test Environment Setup Description | D5: <List enviroment requires in this system 1. Server 2. Database 3. Web Browser ... >
B8: No | C8: Function Name | D8: Sheet Name | E8: Description | F8: Pre-Condition
A9: 1 | B9: F-01 Sign-in (password, Google) | C9: F-01 | D9: Sign-in (password, Google) (FR-AUTH-01, 02); actors: All | E9: Test seed (2 Blocks, 48 students, 7 back-office users); Student signed in
A10: 2 | B10: F-02 Student accounts: verification and list import | C10: F-02 | D10: Student accounts: verification and list import (FR-AUTH-04, 05); actors: Student, Manager | E10: Test seed (2 Blocks, 48 students, 7 back-office users); Student signed in
A11: 3 | B11: F-03 Registration-period request and Term publication | C11: F-03 | D11: Registration-period request and Term publication (FR-CFG-04, 05); actors: Manager, Admin | E11: Test seed (2 Blocks, 48 students, 7 back-office users); Manager signed in
A12: 4 | B12: F-04 Apply for a Term | C12: F-04 | D12: Apply for a Term (FR-APP-01..03); actors: Student | E12: Test seed (2 Blocks, 48 students, 7 back-office users); Student signed in
A13: 5 | B13: F-05 VietQR payment claim and confirmation | C13: F-05 | D13: VietQR payment claim and confirmation (FR-BIL-01..03); actors: Student, Manager | E13: Test seed (2 Blocks, 48 students, 7 back-office users); Student signed in
A14: 6 | B14: F-06 Review, assignment and Round 2 | C14: F-06 | D14: Review, assignment and Round 2 (FR-APP-05, 07, FR-ASG-01..03); actors: Manager, Student, System | E14: Test seed (2 Blocks, 48 students, 7 back-office users); Manager signed in
A15: 7 | B15: F-07 Balance, forfeit and door code release | C15: F-07 | D15: Balance, forfeit and door code release (FR-ASG-04, 11, FR-INV-04); actors: Student, Staff, System | E15: Test seed (2 Blocks, 48 students, 7 back-office users); Student signed in
A16: 8 | B16: F-08 Check-in and check-out desk | C16: F-08 | D16: Check-in and check-out desk (FR-ASG-04, 06); actors: Staff | E16: Test seed (2 Blocks, 48 students, 7 back-office users); Staff signed in
A17: 9 | B17: F-09 Late check-in | C17: F-09 | D17: Late check-in (FR-ASG-05); actors: Student, Staff, Manager | E17: Test seed (2 Blocks, 48 students, 7 back-office users); Student signed in
A18: 10 | B18: F-10 Next-Term requests | C18: F-10 | D18: Next-Term requests (FR-REQ-01..05); actors: Student, Staff | E18: Test seed (2 Blocks, 48 students, 7 back-office users); Staff signed in
A19: 11 | B19: F-11 Requests window, reconciliation and next-Term fees | C19: F-11 | D19: Requests window, reconciliation and next-Term fees (FR-ASG-07, 08, FR-AUTH-08); actors: Manager, System | E19: Test seed (2 Blocks, 48 students, 7 back-office users); System (job) signed in
A20: 12 | B20: F-12 Turnover and operational moves | C20: F-12 | D20: Turnover and operational moves (FR-ASG-10); actors: Staff, Manager | E20: Test seed (2 Blocks, 48 students, 7 back-office users); Staff signed in
... A29: 21 | B29: Non-functional requirements | C29: NFRs | D29: NFR-01 ... NFR-06: metric, threshold and measurement method | E29: See each case

Sheet Test Statistics
B1: TEST STATISTICS
B3: Project Name | C3: CampusStay FPT - Dormitory Registration and Room-Scheduling Management System | E3: Creator
B4: Project Code | C4: FA26SE260 | E4: Reviewer/Approver
B5: Document Code | C5: FA26SE260_Test Report_v1.0 | E5: Issue Date | H5: 30/10/2026
B6: Notes | C6: Review 2 (Iteration 1): 18 mandatory features, 5 main workflows, state transitions of the main entities, 6 NFRs. Round 1 = automated run of mvn verify; manual cases pending.
B10: No | C10: Module code | D10: Passed | E10: Failed | F10: Pending | G10: N/A | H10: Number of test cases
B11: 1 | C11: F-01 Sign-in (password, Google) | D11: ='F-01'!B6 -> 4 | E11: ='F-01'!C6 -> 0 | F11: ='F-01'!D6 -> 0 | G11: ='F-01'!E6 -> 0 | H11: ='F-01'!B4 -> 4
B12: 2 | C12: F-02 Student accounts: verification and list import | D12: ='F-02'!B6 -> 6 | E12: ='F-02'!C6 -> 0 | F12: ='F-02'!D6 -> 0 | G12: ='F-02'!E6 -> 0 | H12: ='F-02'!B4 -> 6
B13: 3 | C13: F-03 Registration-period request and Term publication | D13: ='F-03'!B6 -> 5 | E13: ='F-03'!C6 -> 0 | F13: ='F-03'!D6 -> 0 | G13: ='F-03'!E6 -> 0 | H13: ='F-03'!B4 -> 5
B14: 4 | C14: F-04 Apply for a Term | D14: ='F-04'!B6 -> 5 | E14: ='F-04'!C6 -> 0 | F14: ='F-04'!D6 -> 0 | G14: ='F-04'!E6 -> 0 | H14: ='F-04'!B4 -> 5
B15: 5 | C15: F-05 VietQR payment claim and confirmation | D15: ='F-05'!B6 -> 4 | E15: ='F-05'!C6 -> 0 | F15: ='F-05'!D6 -> 0 | G15: ='F-05'!E6 -> 0 | H15: ='F-05'!B4 -> 4
B16: 6 | C16: F-06 Review, assignment and Round 2 | D16: ='F-06'!B6 -> 8 | E16: ='F-06'!C6 -> 0 | F16: ='F-06'!D6 -> 0 | G16: ='F-06'!E6 -> 0 | H16: ='F-06'!B4 -> 8
B17: 7 | C17: F-07 Balance, forfeit and door code release | D17: ='F-07'!B6 -> 5 | E17: ='F-07'!C6 -> 0 | F17: ='F-07'!D6 -> 0 | G17: ='F-07'!E6 -> 0 | H17: ='F-07'!B4 -> 5
B18: 8 | C18: F-08 Check-in and check-out desk | D18: ='F-08'!B6 -> 5 | E18: ='F-08'!C6 -> 0 | F18: ='F-08'!D6 -> 0 | G18: ='F-08'!E6 -> 0 | H18: ='F-08'!B4 -> 5
B19: 9 | C19: F-09 Late check-in | D19: ='F-09'!B6 -> 3 | E19: ='F-09'!C6 -> 0 | F19: ='F-09'!D6 -> 0 | G19: ='F-09'!E6 -> 0 | H19: ='F-09'!B4 -> 3
B20: 10 | C20: F-10 Next-Term requests | D20: ='F-10'!B6 -> 6 | E20: ='F-10'!C6 -> 0 | F20: ='F-10'!D6 -> 0 | G20: ='F-10'!E6 -> 0 | H20: ='F-10'!B4 -> 6
B21: 11 | C21: F-11 Requests window, reconciliation and next-Term fees | D21: ='F-11'!B6 -> 6 | E21: ='F-11'!C6 -> 0 | F21: ='F-11'!D6 -> 0 | G21: ='F-11'!E6 -> 0 | H21: ='F-11'!B4 -> 6
B22: 12 | C22: F-12 Turnover and operational moves | D22: ='F-12'!B6 -> 3 | E22: ='F-12'!C6 -> 0 | F22: ='F-12'!D6 -> 0 | G22: ='F-12'!E6 -> 0 | H22: ='F-12'!B4 -> 3
B23: 13 | C23: F-13 Maintenance with routing, time limits and escalation | D23: ='F-13'!B6 -> 7 | E23: ='F-13'!C6 -> 0 | F23: ='F-13'!D6 -> 0 | G23: ='F-13'!E6 -> 0 | H23: ='F-13'!B4 -> 7
B24: 14 | C24: F-14 Meter readings and Utility Invoices | D24: ='F-14'!B6 -> 4 | E24: ='F-14'!C6 -> 0 | F24: ='F-14'!D6 -> 0 | G24: ='F-14'!E6 -> 0 | H24: ='F-14'!B4 -> 4
B25: 15 | C25: F-15 Utility debt and termination | D25: ='F-15'!B6 -> 4 | E25: ='F-15'!C6 -> 0 | F25: ='F-15'!D6 -> 0 | G25: ='F-15'!E6 -> 0 | H25: ='F-15'!B4 -> 4
B26: 16 | C26: F-16 Inventory, Room Class by Term, furniture | D26: ='F-16'!B6 -> 4 | E26: ='F-16'!C6 -> 0 | F26: ='F-16'!D6 -> 0 | G26: ='F-16'!E6 -> 0 | H26: ='F-16'!B4 -> 4
B27: 17 | C27: F-17 Notifications, announcements and push | D27: ='F-17'!B6 -> 4 | E27: ='F-17'!C6 -> 0 | F27: ='F-17'!D6 -> 0 | G27: ='F-17'!E6 -> 0 | H27: ='F-17'!B4 -> 4
B28: 18 | C28: F-18 Dashboards, reports, exports and search | D28: ='F-18'!B6 -> 5 | E28: ='F-18'!C6 -> 0 | F28: ='F-18'!D6 -> 0 | G28: ='F-18'!E6 -> 0 | H28: ='F-18'!B4 -> 5
B29: 19 | C29: Main workflows (end to end) | D29: =Workflows!B6 -> 0 | E29: =Workflows!C6 -> 0 | F29: =Workflows!D6 -> 5 | G29: =Workflows!E6 -> 0 | H29: =Workflows!B4 -> 5
B30: 20 | C30: State transitions of the main entities | D30: ='State transitions'!B6 -> 59 | E30: ='State transitions'!C6 -> 0 | F30: ='State transitions'!D6 -> 11 | G30: ='State transitions'!E6 -> 0 | H30: ='State transitions'!B4 -> 70
B31: 21 | C31: Non-functional requirements | D31: =NFRs!B6 -> 2 | E31: =NFRs!C6 -> 0 | F31: =NFRs!D6 -> 4 | G31: =NFRs!E6 -> 0 | H31: =NFRs!B4 -> 6
C33: Sub total | D33: =SUM(D9:D32) -> 149 | E33: =SUM(E9:E32) -> 0 | F33: =SUM(F9:F32) -> 20 | G33: =SUM(G9:G32) -> 0 | H33: =SUM(H9:H32) -> 169
C35: Test coverage | E35: =(D33+E33)*100/(H33-G33) -> 88.16568 | F35: %
C36: Test successful coverage | E36: =D33*100/(H33-G33) -> 88.16568 | F36: %

Sheet F-01
A2: Feature | B2: F-01 Sign-in (password, Google) | R2: Passed
A3: Test requirement | B3: Sign-in (password, Google) (FR-AUTH-01, 02); actors: All | R3: Failed
A4: Number of TCs | B4: =COUNTA(A12:A1000) -> 4 | R4: Pending
A5: Testing Round | B5: Passed | C5: Failed | D5: Pending | E5: N/A | R5: N/A
A6: Round 1 | B6: =COUNTIF($F10:$F998,B5) -> 4 | C6: =COUNTIF($F10:$F998,C5) -> 0 | D6: =COUNTIF($F10:$F998,D5) -> 0 | E6: =COUNTIF($F10:$F998,E5) -> 0
A7: Round 2 | B7: 0 | C7: 0 | D7: 0 | E7: 0
A8: Round 3 | B8: 0 | C8: 0 | D8: 0 | E8: 0
A10: Test Case ID | B10: Test Case Description | C10: Test Case Procedure | D10: Expected Results | E10: Pre-conditions | F10: Round 1 | G10: Test date | H10: Tester | I10: Round 2 | J10: Test date | K10: Tester | L10: Round 3 | M10: Test date | N10: Tester | O10: Note
A11: FR-AUTH-01, 02
A12: TC-F01-01 | B12: [Main] Valid credentials return a token and the contract user shape. | C12: Automated (AuthFlowIT.signInReturnsTokenAndUser): POST /api/auth/sign-in; check the answer and the database | D12: Valid credentials return a token and the contract user shape. | E12: Test seed (2 Blocks, 48 students, 7 back-office users); Student signed in | F12: Passed | G12: 30/10/2026 | H12: CI (mvn verify)
A13: TC-F01-02 | B13: [Main] An unknown FPT Google account signs up as a student without a password; until it sets one only the setup endpoints answer; the password follows the usual rules and is set once. | C13: Automated (GoogleSignUpIT.signUpThenSetAPassword): POST /api/auth/google; POST /api/auth/password/set; GET, PUT /api/students/me/verification; check the answer and the database | D13: An unknown FPT Google account signs up as a student without a password; until it sets one only the setup endpoints answer; the password follows the usual rules and is set once. | E13: Test seed (2 Blocks, 48 students, 7 back-office users); Student signed in | F13: Passed | G13: 30/10/2026 | H13: CI (mvn verify)
A14: TC-F01-03 | B14: [Rule] The 5th wrong password locks the account, even for the right password. | C14: Automated (AuthFlowIT.accountLocksAfterMaxFailedAttempts): POST /api/auth/sign-in; check the answer and the database | D14: The 5th wrong password locks the account, even for the right password. | E14: Test seed (2 Blocks, 48 students, 7 back-office users); Student signed in | F14: Passed | G14: 30/10/2026 | H14: CI (mvn verify)
A15: TC-F01-04 | B15: [Exception] No token → 401; a student calling an Admin endpoint → 403. | C15: Automated (AuthFlowIT.roleRulesAreEnforced): GET /api/auth/me; check the answer and the database | D15: No token → 401; a student calling an Admin endpoint → 403. | E15: Test seed (2 Blocks, 48 students, 7 back-office users); Student signed in | F15: Passed | G15: 30/10/2026 | H15: CI (mvn verify)

Sheet F-02
A2: Feature | B2: F-02 Student accounts: verification and list import | R2: Passed
A3: Test requirement | B3: Student accounts: verification and list import (FR-AUTH-04, 05); actors: Student, Manager | R3: Failed
A4: Number of TCs | B4: =COUNTA(A12:A1000) -> 6 | R4: Pending
A5: Testing Round | B5: Passed | C5: Failed | D5: Pending | E5: N/A | R5: N/A
A6: Round 1 | B6: =COUNTIF($F10:$F998,B5) -> 6 | C6: =COUNTIF($F10:$F998,C5) -> 0 | D6: =COUNTIF($F10:$F998,D5) -> 0 | E6: =COUNTIF($F10:$F998,E5) -> 0
A7: Round 2 | B7: 0 | C7: 0 | D7: 0 | E7: 0
A8: Round 3 | B8: 0 | C8: 0 | D8: 0 | E8: 0
A10: Test Case ID | B10: Test Case Description | C10: Test Case Procedure | D10: Expected Results | E10: Pre-conditions | F10: Round 1 | G10: Test date | H10: Tester | I10: Round 2 | J10: Test date | K10: Tester | L10: Round 3 | M10: Test date | N10: Tester | O10: Note
A11: FR-AUTH-04, 05
A12: TC-F02-01 | B12: [Main] The sign-up form checks every field and the student code; once sent the account is Pending verification, every Manager is told, and the student cannot apply. | C12: Automated (GoogleSignUpIT.signUpFormWaitsForAManager): GET, PUT /api/students/me/verification; check the answer and the database | D12: The sign-up form checks every field and the student code; once sent the account is Pending verification, every Manager is told, and the student cannot apply. | E12: Test seed (2 Blocks, 48 students, 7 back-office users); Student signed in | F12: Passed | G12: 30/10/2026 | H12: CI (mvn verify)
A13: TC-F02-02 | B13: [Main] A Manager verifies a pending account (the student is told) or rejects it (locked); locking signs the student out until a Manager unlocks the account; a rejected account comes back as pending. | C13: Automated (StudentAccountsIT.verifyRejectLockUnlock): POST /api/student-accounts/{id}/verify; POST /api/student-accounts/{id}/reject; POST /api/student-accounts/{id}/lock; POST /api/student-accounts/{id}/unlock; check the answer and the database | D13: A Manager verifies a pending account (the student is told) or rejects it (locked); locking signs the student out until a Manager unlocks the account; a rejected account comes back as pending. | E13: Test seed (2 Blocks, 48 students, 7 back-office users); Manager signed in | F13: Passed | G13: 30/10/2026 | H13: CI (mvn verify)
A14: TC-F02-03 | B14: [Rule] The template names the columns; an upload is previewed line by line (New, Update, Unchanged, Error with the reason) and counts the students the file leaves out; nothing changes before the confirmation. | C14: Automated (StudentImportIT.previewsTheFile): GET /api/student-imports/template; POST /api/student-imports; check the answer and the database | D14: The template names the columns; an upload is previewed line by line (New, Update, Unchanged, Error with the reason) and counts the students the file leaves out; nothing changes before the confirmation. | E14: Test seed (2 Blocks, 48 students, 7 back-office users); Manager signed in | F14: Passed | G14: 30/10/2026 | H14: CI (mvn verify)
A15: TC-F02-04 | B15: [Main] Confirming creates and updates the accounts, verifies the waiting one that matches, gives a fictional student's code to the real student, marks real students missing from the file Not enrolled (never fictional ones), is written to the Audit Log and cannot run twice. | C15: Automated (StudentImportIT.confirmAppliesTheFile): GET /api/student-imports; POST /api/student-imports/{id}/confirm; check the answer and the database | D15: Confirming creates and updates the accounts, verifies the waiting one that matches, gives a fictional student's code to the real student, marks real students missing from the file Not enrolled (never fictional ones), is written to the Audit Log and cannot run twice. | E15: Test seed (2 Blocks, 48 students, 7 back-office users); Manager signed in | F15: Passed | G15: 30/10/2026 | H15: CI (mvn verify)
A16: TC-F02-05 | B16: [Rule] A major is read from its code, its English label or its Vietnamese name, the other FPT majors are in the list (V61), and a student-code prefix such as SS put in the major column gets an error that says so; the file is the XLSX the template writer makes. | C16: Automated (StudentImportIT.readsMajorsByCodeOrNameAndExplainsCodePrefixes): run the scenario and check the result | D16: A major is read from its code, its English label or its Vietnamese name, the other FPT majors are in the list (V61), and a student-code prefix such as SS put in the major column gets an error that says so; the file is the XLSX the template writer makes. | E16: Test seed (2 Blocks, 48 students, 7 back-office users); Manager signed in | F16: Passed | G16: 30/10/2026 | H16: CI (mvn verify)
A17: TC-F02-06 | B17: [Exception] Only a verified account may apply: a pending one sees why and is refused (ADR-26). | C17: Automated (StudentAccountsIT.pendingAccountCannotApply): POST /api/student-accounts/{id}/verify; check the answer and the database | D17: Only a verified account may apply: a pending one sees why and is refused (ADR-26). | E17: Test seed (2 Blocks, 48 students, 7 back-office users); Student signed in | F17: Passed | G17: 30/10/2026 | H17: CI (mvn verify)

Sheet F-03
A2: Feature | B2: F-03 Registration-period request and Term publication | R2: Passed
A3: Test requirement | B3: Registration-period request and Term publication (FR-CFG-04, 05); actors: Manager, Admin | R3: Failed
A4: Number of TCs | B4: =COUNTA(A12:A1000) -> 5 | R4: Pending
A5: Testing Round | B5: Passed | C5: Failed | D5: Pending | E5: N/A | R5: N/A
A6: Round 1 | B6: =COUNTIF($F10:$F998,B5) -> 5 | C6: =COUNTIF($F10:$F998,C5) -> 0 | D6: =COUNTIF($F10:$F998,D5) -> 0 | E6: =COUNTIF($F10:$F998,E5) -> 0
A7: Round 2 | B7: 0 | C7: 0 | D7: 0 | E7: 0
A8: Round 3 | B8: 0 | C8: 0 | D8: 0 | E8: 0
A10: Test Case ID | B10: Test Case Description | C10: Test Case Procedure | D10: Expected Results | E10: Pre-conditions | F10: Round 1 | G10: Test date | H10: Tester | I10: Round 2 | J10: Test date | K10: Tester | L10: Round 3 | M10: Test date | N10: Tester | O10: Note
A11: FR-CFG-04, 05
A12: TC-F03-01 | B12: [Main] A Manager files a request; it is Submitted with its proposal and history, every Admin and every other Manager is notified with a link to the requests list, and the requester is not. | C12: Automated (TermRequestIT.managerFilesARequest): GET /api/term-requests; GET /api/term-requests/{id}; POST /api/term-requests; check the answer and the database | D12: A Manager files a request; it is Submitted with its proposal and history, every Admin and every other Manager is notified with a link to the requests list, and the requester is not. | E12: Test seed (2 Blocks, 48 students, 7 back-office users); Manager signed in | F12: Passed | G12: 30/10/2026 | H12: CI (mvn verify)
A13: TC-F03-02 | B13: [Main] The Admin builds the Draft from a Manager's request: it holds the request's dates, Blocks, Rooms and prices, the request is In progress (the Manager is told) and building again opens the same Draft; a price that differs from the request needs a reason, which the request then shows next to the difference. | C13: Automated (TermWizardIT.buildsTheTermFromARequest): GET /api/term-requests/{id}; POST /api/admin/terms/drafts; GET /api/admin/terms/{id}/wizard; PUT /api/admin/terms/{id}/wizard/{step}; check the answer and the database | D13: The Admin builds the Draft from a Manager's request: it holds the request's dates, Blocks, Rooms and prices, the request is In progress (the Manager is told) and building again opens the same Draft; a price that differs from the request needs a reason, which the request then shows next to the difference. | E13: Test seed (2 Blocks, 48 students, 7 back-office users); Admin signed in | F13: Passed | G13: 30/10/2026 | H13: CI (mvn verify)
A14: TC-F03-03 | B14: [Rule] The Timeline step checks spec §5.2 per field: registration closing before it opens, renewal milestones filled in only partly or out of order, Check-in before the Term before is left. | C14: Automated (TermWizardIT.timelineFollowsTheRules): POST /api/admin/terms/drafts; PUT /api/admin/terms/{id}/wizard/{step}; check the answer and the database | D14: The Timeline step checks spec §5.2 per field: registration closing before it opens, renewal milestones filled in only partly or out of order, Check-in before the Term before is left. | E14: Test seed (2 Blocks, 48 students, 7 back-office users); Admin signed in | F14: Passed | G14: 30/10/2026 | H14: CI (mvn verify)
A15: TC-F03-04 | B15: [Rule] A Draft with unsaved steps cannot be published; once every step is saved, publishing fixes the Term's prices, Deposit and rules, tells every Manager (Term dashboard link) and puts the Term announcement on the students' board and bell. A later default-price change leaves the Term's prices alone, an Application pays the Term's Deposit, and once an Invoice exists the prices are locked. | C15: Automated (TermWizardIT.publishingFixesTheTerm): POST /api/admin/terms/{id}/publish; GET /api/catalog; POST /api/admin/terms/drafts; GET /api/admin/terms/{id}/wizard; check the answer and the database | D15: A Draft with unsaved steps cannot be published; once every step is saved, publishing fixes the Term's prices, Deposit and rules, tells every Manager (Term dashboard link) and puts the Term announcement on the students' board and bell. A later default-price change leaves the Term's prices alone, an Application pays the Term's Deposit, and once an Invoice exists the prices are locked. | E15: Test seed (2 Blocks, 48 students, 7 back-office users); Admin signed in | F15: Passed | G15: 30/10/2026 | H15: CI (mvn verify)
A16: TC-F03-05 | B16: [Exception] Missing fields and an unknown Block are named per field; a second open request for the same Term is refused; Staff and students cannot file or read requests. | C16: Automated (TermRequestIT.refusesInvalidAndDuplicateRequests): POST /api/term-requests; check the answer and the database | D16: Missing fields and an unknown Block are named per field; a second open request for the same Term is refused; Staff and students cannot file or read requests. | E16: Test seed (2 Blocks, 48 students, 7 back-office users); Manager signed in | F16: Passed | G16: 30/10/2026 | H16: CI (mvn verify)

Sheet F-04
A2: Feature | B2: F-04 Apply for a Term | R2: Passed
A3: Test requirement | B3: Apply for a Term (FR-APP-01..03); actors: Student | R3: Failed
A4: Number of TCs | B4: =COUNTA(A12:A1000) -> 5 | R4: Pending
A5: Testing Round | B5: Passed | C5: Failed | D5: Pending | E5: N/A | R5: N/A
A6: Round 1 | B6: =COUNTIF($F10:$F998,B5) -> 5 | C6: =COUNTIF($F10:$F998,C5) -> 0 | D6: =COUNTIF($F10:$F998,D5) -> 0 | E6: =COUNTIF($F10:$F998,E5) -> 0
A7: Round 2 | B7: 0 | C7: 0 | D7: 0 | E7: 0
A8: Round 3 | B8: 0 | C8: 0 | D8: 0 | E8: 0
A10: Test Case ID | B10: Test Case Description | C10: Test Case Procedure | D10: Expected Results | E10: Pre-conditions | F10: Round 1 | G10: Test date | H10: Tester | I10: Round 2 | J10: Test date | K10: Tester | L10: Round 3 | M10: Test date | N10: Tester | O10: Note
A11: FR-APP-01..03
A12: TC-F04-01 | B12: [Main] Submit with a Deposit Invoice, then the list, detail, Home and notification; a second one is refused. | C12: Automated (ApplicationsIT.submitsApplicationWithDeposit): POST /api/applications; GET /api/applications/{id}; GET /api/students/me/applications; GET /api/students/me/home; check the answer and the database | D12: Submit with a Deposit Invoice, then the list, detail, Home and notification; a second one is refused. | E12: Test seed (2 Blocks, 48 students, 7 back-office users); Student signed in | F12: Passed | G12: 30/10/2026 | H12: CI (mvn verify)
A13: TC-F04-02 | B13: [Main] An invited pair reaches the office together: the first to pay waits as Awaiting Roommate; both are Submitted when the second Deposit is paid. | C13: Automated (ApplicationsIT.invitedPairIsSubmittedTogether): POST /api/applications; GET /api/applications/{id}; POST /api/roommate-invitations/{id}/respond; GET /api/students/me/applications; check the answer and the database | D13: An invited pair reaches the office together: the first to pay waits as Awaiting Roommate; both are Submitted when the second Deposit is paid. | E13: Test seed (2 Blocks, 48 students, 7 back-office users); Student signed in | F13: Passed | G13: 30/10/2026 | H13: CI (mvn verify)
A14: TC-F04-03 | B14: [Rule] The stay length (spec §6.6, D-13) is 1 to stay.max_terms, capped by the semesters the student has left (stay.program_semesters); it is kept on the Application and shown to the student and the back office; a student who already holds a Bed for the Term cannot apply (not a continuing resident). | C14: Automated (ApplicationsIT.stayTermsOnTheApplication): POST /api/applications; GET /api/applications/eligibility; check the answer and the database | D14: The stay length (spec §6.6, D-13) is 1 to stay.max_terms, capped by the semesters the student has left (stay.program_semesters); it is kept on the Application and shown to the student and the back office; a student who already holds a Bed for the Term cannot apply (not a continuing resident). | E14: Test seed (2 Blocks, 48 students, 7 back-office users); Student signed in | F14: Passed | G14: 30/10/2026 | H14: CI (mvn verify)
A15: TC-F04-04 | B15: [Rule] Contact, consent and roommate rules are named per field. | C15: Automated (ApplicationsIT.applicationIsValidated): POST /api/applications; check the answer and the database | D15: Contact, consent and roommate rules are named per field. | E15: Test seed (2 Blocks, 48 students, 7 back-office users); Student signed in | F15: Passed | G15: 30/10/2026 | H15: CI (mvn verify)
A16: TC-F04-05 | B16: [Exception] Staff cannot use student screens; another student's Application is 404. | C16: Automated (ApplicationsIT.applicationsArePrivate): GET /api/applications/{id}; POST /api/applications/{id}/cancel; GET /api/students/me/home; GET /api/students/me/profile; check the answer and the database | D16: Staff cannot use student screens; another student's Application is 404. | E16: Test seed (2 Blocks, 48 students, 7 back-office users); Staff signed in | F16: Passed | G16: 30/10/2026 | H16: CI (mvn verify)

Sheet F-05
A2: Feature | B2: F-05 VietQR payment claim and confirmation | R2: Passed
A3: Test requirement | B3: VietQR payment claim and confirmation (FR-BIL-01..03); actors: Student, Manager | R3: Failed
A4: Number of TCs | B4: =COUNTA(A12:A1000) -> 4 | R4: Pending
A5: Testing Round | B5: Passed | C5: Failed | D5: Pending | E5: N/A | R5: N/A
A6: Round 1 | B6: =COUNTIF($F10:$F998,B5) -> 4 | C6: =COUNTIF($F10:$F998,C5) -> 0 | D6: =COUNTIF($F10:$F998,D5) -> 0 | E6: =COUNTIF($F10:$F998,E5) -> 0
A7: Round 2 | B7: 0 | C7: 0 | D7: 0 | E7: 0
A8: Round 3 | B8: 0 | C8: 0 | D8: 0 | E8: 0
A10: Test Case ID | B10: Test Case Description | C10: Test Case Procedure | D10: Expected Results | E10: Pre-conditions | F10: Round 1 | G10: Test date | H10: Tester | I10: Round 2 | J10: Test date | K10: Tester | L10: Round 3 | M10: Test date | N10: Tester | O10: Note
A11: FR-BIL-01..03
A12: TC-F05-01 | B12: [Main] The claim waits for a Manager and stops the Deposit window (the Application does not expire); the queue lists it with the count and total; a bulk confirmation pays each Invoice at the time of its claim, one audit entry each, and the Applications are submitted; unknown Invoices are skipped. | C12: Automated (PaymentClaimIT.claimStopsTheClockAndBulkConfirmationPays): GET /api/invoices/{id}/payment; GET /api/students/me/invoices; POST /api/invoices/{id}/claim; GET /api/payment-claims; check the answer and the database | D12: The claim waits for a Manager and stops the Deposit window (the Application does not expire); the queue lists it with the count and total; a bulk confirmation pays each Invoice at the time of its claim, one audit entry each, and the Applications are submitted; unknown Invoices are skipped. | E12: Test seed (2 Blocks, 48 students, 7 back-office users); Student signed in | F12: Passed | G12: 30/10/2026 | H12: CI (mvn verify)
A13: TC-F05-02 | B13: [Main] A student reads and saves their refund account; the number keeps its digits only, each field is checked, and only students have one. | C13: Automated (RefundAccountIT.studentKeepsTheirRefundAccount): GET /api/students/me/refund-account; PUT /api/students/me/refund-account; check the answer and the database | D13: A student reads and saves their refund account; the number keeps its digits only, each field is checked, and only students have one. | E13: Test seed (2 Blocks, 48 students, 7 back-office users); Student signed in | F13: Passed | G13: 30/10/2026 | H13: CI (mvn verify)
A14: TC-F05-03 | B14: [Rule] A rejection needs a reason; the Invoice is Unpaid again and the deadline continues with the time that was left (at least payment.rejected_claim_min_hours); the student is told; a second rejection cancels the Deposit and the Application expires. | C14: Automated (PaymentClaimIT.rejectionsGiveTimeBackThenCancel): GET /api/invoices/{id}/payment; POST /api/invoices/{id}/claim; POST /api/payment-claims/reject; check the answer and the database | D14: A rejection needs a reason; the Invoice is Unpaid again and the deadline continues with the time that was left (at least payment.rejected_claim_min_hours); the student is told; a second rejection cancels the Deposit and the Application expires. | E14: Test seed (2 Blocks, 48 students, 7 back-office users); Manager signed in | F14: Passed | G14: 30/10/2026 | H14: CI (mvn verify)
A15: TC-F05-04 | B15: [Exception] One claim at a time; a paid or void Invoice and a Deposit past its deadline cannot be claimed; a student cannot cancel while a claim waits; only Managers see the queue and decide; an empty selection is refused; Invoices without a claim are skipped. | C15: Automated (PaymentClaimIT.claimRules): POST /api/invoices/{id}/claim; GET /api/payment-claims; POST /api/payment-claims/confirm; POST /api/payment-claims/reject; check the answer and the database | D15: One claim at a time; a paid or void Invoice and a Deposit past its deadline cannot be claimed; a student cannot cancel while a claim waits; only Managers see the queue and decide; an empty selection is refused; Invoices without a claim are skipped. | E15: Test seed (2 Blocks, 48 students, 7 back-office users); Student signed in | F15: Passed | G15: 30/10/2026 | H15: CI (mvn verify)

Sheet F-06
A2: Feature | B2: F-06 Review, assignment and Round 2 | R2: Passed
A3: Test requirement | B3: Review, assignment and Round 2 (FR-APP-05, 07, FR-ASG-01..03); actors: Manager, Student, System | R3: Failed
A4: Number of TCs | B4: =COUNTA(A12:A1000) -> 8 | R4: Pending
A5: Testing Round | B5: Passed | C5: Failed | D5: Pending | E5: N/A | R5: N/A
A6: Round 1 | B6: =COUNTIF($F10:$F998,B5) -> 8 | C6: =COUNTIF($F10:$F998,C5) -> 0 | D6: =COUNTIF($F10:$F998,D5) -> 0 | E6: =COUNTIF($F10:$F998,E5) -> 0
A7: Round 2 | B7: 0 | C7: 0 | D7: 0 | E7: 0
A8: Round 3 | B8: 0 | C8: 0 | D8: 0 | E8: 0
A10: Test Case ID | B10: Test Case Description | C10: Test Case Procedure | D10: Expected Results | E10: Pre-conditions | F10: Round 1 | G10: Test date | H10: Tester | I10: Round 2 | J10: Test date | K10: Tester | L10: Round 3 | M10: Test date | N10: Tester | O10: Note
A11: FR-APP-05, 07, FR-ASG-01..03
A12: TC-F06-01 | B12: [Main] The Manager approves in bulk, runs, resolves the conflict to the waitlist and commits the Block, which approves it at once (ADR-19): Allocations, Balance Invoices, notifications and My Room. Staff cannot commit. | C12: Automated (AssignmentIT.assignmentRunToAllocation): GET /api/students/me/home; POST /api/applications/bulk-review; GET /api/approvals/assignment; GET /api/assignment-runs; check the answer and the database | D12: The Manager approves in bulk, runs, resolves the conflict to the waitlist and commits the Block, which approves it at once (ADR-19): Allocations, Balance Invoices, notifications and My Room. Staff cannot commit. | E12: Test seed (2 Blocks, 48 students, 7 back-office users); Manager signed in | F12: Passed | G12: 30/10/2026 | H12: CI (mvn verify)
A13: TC-F06-02 | B13: [Main] A Manager runs Round 2 (M8): the Waitlisted students without an open offer get held options on the Term's free Beds, by the rules of the offers made when a Block is approved; students may not run it. The Manager's list shows who is waiting without an offer, then who got one with its options (A-58). | C13: Automated (Round2IT.managerRunsRound2): GET /api/round2; POST /api/round2/run; GET /api/round2/offers; check the answer and the database | D13: A Manager runs Round 2 (M8): the Waitlisted students without an open offer get held options on the Term's free Beds, by the rules of the offers made when a Block is approved; students may not run it. The Manager's list shows who is waiting without an offer, then who got one with its options (A-58). | E13: Test seed (2 Blocks, 48 students, 7 back-office users); Manager signed in | F13: Passed | G13: 30/10/2026 | H13: CI (mvn verify)
A14: TC-F06-03 | B14: [Main] A waitlisted student sees the open offer, the day the waitlist ends and the refund; withdrawing closes the offer, releases its Beds, cancels the Application and asks a Manager to refund the whole Deposit, whose list shows the student's bank account (A-61, A-62). A plain cancel is refused, and only one's own waitlisted Application can be withdrawn. | C14: Automated (Round2IT.waitlistedStudentWithdraws): POST /api/applications/{id}/withdraw; PUT /api/students/me/refund-account; check the answer and the database | D14: A waitlisted student sees the open offer, the day the waitlist ends and the refund; withdrawing closes the offer, releases its Beds, cancels the Application and asks a Manager to refund the whole Deposit, whose list shows the student's bank account (A-61, A-62). A plain cancel is refused, and only one's own waitlisted Application can be withdrawn. | E14: Test seed (2 Blocks, 48 students, 7 back-office users); Student signed in | F14: Passed | G14: 30/10/2026 | H14: CI (mvn verify)
A15: TC-F06-04 | B15: [Rule] The queue, the review view (opening it starts the review), rejection needs a note, once only. | C15: Automated (AssignmentIT.reviewQueueAndRejection): GET /api/applications/{id}; GET /api/applications; POST /api/applications/{id}/review; check the answer and the database | D15: The queue, the review view (opening it starts the review), rejection needs a note, once only. | E15: Test seed (2 Blocks, 48 students, 7 back-office users); Manager signed in | F15: Passed | G15: 30/10/2026 | H15: CI (mvn verify)
A16: TC-F06-05 | B16: [Rule] The priority group goes first; the same input gives the same proposal. | C16: Automated (AssignmentEngineTest.priorityOrderAndDeterminism): POST /api/assignment-runs; check the answer and the database | D16: The priority group goes first; the same input gives the same proposal. | E16: Test seed (2 Blocks, 48 students, 7 back-office users); Manager signed in | F16: Passed | G16: 30/10/2026 | H16: CI (mvn verify)
A17: TC-F06-06 | B17: [Rule] When the Term's check-in starts, a waitlisted Application without an open offer is cancelled with the whole Deposit to refund and the student is told; one with an open offer keeps it until it is answered. | C17: Automated (Round2IT.waitlistEndsWhenCheckInStarts): run the scenario and check the result | D17: When the Term's check-in starts, a waitlisted Application without an open offer is cancelled with the whole Deposit to refund and the student is told; one with an open offer keeps it until it is answered. | E17: Test seed (2 Blocks, 48 students, 7 back-office users); System (job) signed in | F17: Passed | G17: 30/10/2026 | H17: CI (mvn verify)
A18: TC-F06-07 | B18: [Exception] A dry run is a preview; students and Staff cannot use runs (ADR-19). | C18: Automated (AssignmentIT.dryRunAndPermissions): GET /api/approvals/assignment; GET /api/assignment-runs; POST /api/assignment-runs; POST /api/assignment-runs/{runId}/commit; check the answer and the database | D18: A dry run is a preview; students and Staff cannot use runs (ADR-19). | E18: Test seed (2 Blocks, 48 students, 7 back-office users); Staff signed in | F18: Passed | G18: 30/10/2026 | H18: CI (mvn verify)
A19: TC-F06-08 | B19: [Exception] Every Manager sees every Block's Applications (ADR-19); Staff and students cannot review. | C19: Automated (AssignmentIT.reviewIsScopedByBlock): GET /api/applications/{id}; GET /api/applications; POST /api/applications/{id}/review; check the answer and the database | D19: Every Manager sees every Block's Applications (ADR-19); Staff and students cannot review. | E19: Test seed (2 Blocks, 48 students, 7 back-office users); Staff signed in | F19: Passed | G19: 30/10/2026 | H19: CI (mvn verify)

Sheet F-07
A2: Feature | B2: F-07 Balance, forfeit and door code release | R2: Passed
A3: Test requirement | B3: Balance, forfeit and door code release (FR-ASG-04, 11, FR-INV-04); actors: Student, Staff, System | R3: Failed
A4: Number of TCs | B4: =COUNTA(A12:A1000) -> 5 | R4: Pending
A5: Testing Round | B5: Passed | C5: Failed | D5: Pending | E5: N/A | R5: N/A
A6: Round 1 | B6: =COUNTIF($F10:$F998,B5) -> 5 | C6: =COUNTIF($F10:$F998,C5) -> 0 | D6: =COUNTIF($F10:$F998,D5) -> 0 | E6: =COUNTIF($F10:$F998,E5) -> 0
A7: Round 2 | B7: 0 | C7: 0 | D7: 0 | E7: 0
A8: Round 3 | B8: 0 | C8: 0 | D8: 0 | E8: 0
A10: Test Case ID | B10: Test Case Description | C10: Test Case Procedure | D10: Expected Results | E10: Pre-conditions | F10: Round 1 | G10: Test date | H10: Tester | I10: Round 2 | J10: Test date | K10: Tester | L10: Round 3 | M10: Test date | N10: Tester | O10: Note
A11: FR-ASG-04, 11, FR-INV-04
A12: TC-F07-01 | B12: [Main] Assigned and unpaid (yellow); paid but before the check-in start, then without a Room code, the student waits (no code); Staff confirm the Room's code and it is released: the student is a resident (orange), is told and sees the code; a student who pays later receives the current code at once. | C12: Automated (ResidenceIT.doorCodeIsReleasedToPaidResidents): GET /api/inventory/rooms; GET /api/students/me/allocation; GET /api/students/me/door-code; check the answer and the database | D12: Assigned and unpaid (yellow); paid but before the check-in start, then without a Room code, the student waits (no code); Staff confirm the Room's code and it is released: the student is a resident (orange), is told and sees the code; a student who pays later receives the current code at once. | E12: Test seed (2 Blocks, 48 students, 7 back-office users); Student signed in | F12: Passed | G12: 30/10/2026 | H12: CI (mvn verify)
A13: TC-F07-02 | B13: [Main] Staff draw a random code, read it to set the lock, confirm it, and it becomes the Room's code; the database holds it encrypted and every view is in the Audit Log. | C13: Automated (DoorCodeIT.proposesConfirmsAndReveals): GET /api/door-codes; POST /api/door-codes/{room}; POST /api/door-codes/{room}/confirm; POST /api/door-codes/{room}/reveal; check the answer and the database | D13: Staff draw a random code, read it to set the lock, confirm it, and it becomes the Room's code; the database holds it encrypted and every view is in the Audit Log. | E13: Test seed (2 Blocks, 48 students, 7 back-office users); Staff signed in | F13: Passed | G13: 30/10/2026 | H13: CI (mvn verify)
A14: TC-F07-03 | B14: [Main] A student whose Balance is paid and whose check-in start has come waits for the Room's code; once Staff confirm it, it is released to them (spec §6.8): they are told (never the code), see it and become a resident; without a Bed there is nothing to show. | C14: Automated (DoorCodeIT.showsTheStudentTheirCode): GET /api/students/me/door-code; POST /api/students/me/door-code/reveal; GET /api/students/me/furniture; check the answer and the database | D14: A student whose Balance is paid and whose check-in start has come waits for the Room's code; once Staff confirm it, it is released to them (spec §6.8): they are told (never the code), see it and become a resident; without a Bed there is nothing to show. | E14: Test seed (2 Blocks, 48 students, 7 back-office users); Student signed in | F14: Passed | G14: 30/10/2026 | H14: CI (mvn verify)
A15: TC-F07-04 | B15: [Rule] A Balance past its deadline without a claim is forfeited: the Allocation is cancelled, the Balance void, the Application Forfeited, the Deposit kept by the rule "Balance not paid" (a 0 % rule records no refund; a 10 % rule one refund, never two) and the student told; a claim waiting keeps the Bed, and so does a later Balance deadline a Manager chose when approving a late check-in, which may not pass the arrival day (the Balance is paid before check-in). | C15: Automated (ResidenceIT.unpaidBalanceIsForfeited): GET /api/inventory/rooms; POST /api/late-check-ins/{id}/decision; POST /api/students/me/late-check-in; check the answer and the database | D15: A Balance past its deadline without a claim is forfeited: the Allocation is cancelled, the Balance void, the Application Forfeited, the Deposit kept by the rule "Balance not paid" (a 0 % rule records no refund; a 10 % rule one refund, never two) and the student told; a claim waiting keeps the Bed, and so does a later Balance deadline a Manager chose when approving a late check-in, which may not pass the arrival day (the Balance is paid before check-in). | E15: Test seed (2 Blocks, 48 students, 7 back-office users); System (job) signed in | F15: Passed | G15: 30/10/2026 | H15: CI (mvn verify)
A16: TC-F07-05 | B16: [Exception] Codes are 6 new digits; other Blocks and other roles are refused. | C16: Automated (DoorCodeIT.refusesWrongCodes): GET /api/door-codes; POST /api/door-codes/{room}; POST /api/door-codes/{room}/confirm; POST /api/door-codes/{room}/cancel; check the answer and the database | D16: Codes are 6 new digits; other Blocks and other roles are refused. | E16: Test seed (2 Blocks, 48 students, 7 back-office users); Staff signed in | F16: Passed | G16: 30/10/2026 | H16: CI (mvn verify)

Sheet F-08
A2: Feature | B2: F-08 Check-in and check-out desk | R2: Passed
A3: Test requirement | B3: Check-in and check-out desk (FR-ASG-04, 06); actors: Staff | R3: Failed
A4: Number of TCs | B4: =COUNTA(A12:A1000) -> 5 | R4: Pending
A5: Testing Round | B5: Passed | C5: Failed | D5: Pending | E5: N/A | R5: N/A
A6: Round 1 | B6: =COUNTIF($F10:$F998,B5) -> 5 | C6: =COUNTIF($F10:$F998,C5) -> 0 | D6: =COUNTIF($F10:$F998,D5) -> 0 | E6: =COUNTIF($F10:$F998,E5) -> 0
A7: Round 2 | B7: 0 | C7: 0 | D7: 0 | E7: 0
A8: Round 3 | B8: 0 | C8: 0 | D8: 0 | E8: 0
A10: Test Case ID | B10: Test Case Description | C10: Test Case Procedure | D10: Expected Results | E10: Pre-conditions | F10: Round 1 | G10: Test date | H10: Tester | I10: Round 2 | J10: Test date | K10: Tester | L10: Round 3 | M10: Test date | N10: Tester | O10: Note
A11: FR-ASG-04, 06
A12: TC-F08-01 | B12: [Main] The Balance includes the Utility Deposit; until it is paid the desk blocks check-in; then the student checks in with the hand-over items, once only. | C12: Automated (DeskIT.checkInNeedsBalanceAndUtilityDeposit): POST /api/check-in; GET /api/check-in/lookup; GET /api/check-in/today; check the answer and the database | D12: The Balance includes the Utility Deposit; until it is paid the desk blocks check-in; then the student checks in with the hand-over items, once only. | E12: Test seed (2 Blocks, 48 students, 7 back-office users); Staff signed in | F12: Passed | G12: 30/10/2026 | H12: CI (mvn verify)
A13: TC-F08-02 | B13: [Main] Check-out settles the Utility Deposit: the share since the Room's last reading, the damage charge, the refund to the Manager; the Bed is free again, the figures stay as settled and the Room's door code must change. | C13: Automated (DeskIT.checkOutSettlesTheDeposit): GET /api/check-out; GET /api/check-out/{allocationId}; POST /api/check-out/{allocationId}; check the answer and the database | D13: Check-out settles the Utility Deposit: the share since the Room's last reading, the damage charge, the refund to the Manager; the Bed is free again, the figures stay as settled and the Room's door code must change. | E13: Test seed (2 Blocks, 48 students, 7 back-office users); Staff signed in | F13: Passed | G13: 30/10/2026 | H13: CI (mvn verify)
A14: TC-F08-03 | B14: [Main] The desk enters the final meter readings Room by Room, typed or from the XLSX template, before the leavers come: each Room's reading goes to the check-out drafts of its leavers; a Room without leavers in the user's Blocks or a reading below the Room's last one is reported and not saved. | C14: Automated (DeskIT.finalReadingsRoomByRoom): GET /api/check-out/readings; PUT /api/check-out/readings; GET /api/check-out/readings/template; check the answer and the database | D14: The desk enters the final meter readings Room by Room, typed or from the XLSX template, before the leavers come: each Room's reading goes to the check-out drafts of its leavers; a Room without leavers in the user's Blocks or a reading below the Room's last one is reported and not saved. | E14: Test seed (2 Blocks, 48 students, 7 back-office users); Staff signed in | F14: Passed | G14: 30/10/2026 | H14: CI (mvn verify)
A15: TC-F08-04 | B15: [Rule] Check-out records the damage of each furniture item of the Room (spec §6.16): the damage charge is their sum, a damaged item becomes Broken with the reason in its history, an item of another Room is refused; the list shows the Term's check-out date and whether a leaver is past it. | C15: Automated (DeskIT.checkOutRecordsDamagePerItem): run the scenario and check the result | D15: Check-out records the damage of each furniture item of the Room (spec §6.16): the damage charge is their sum, a damaged item becomes Broken with the reason in its history, an item of another Room is refused; the list shows the Term's check-out date and whether a leaver is past it. | E15: Test seed (2 Blocks, 48 students, 7 back-office users); Staff signed in | F15: Passed | G15: 30/10/2026 | H15: CI (mvn verify)
A16: TC-F08-05 | B16: [Exception] Another Block's Staff do not find the student, every Manager does (ADR-19); students and the Admin have no desk. | C16: Automated (DeskIT.deskIsScoped): GET /api/check-in/lookup; GET /api/check-in/today; GET /api/check-out; GET /api/check-out/{allocationId}; check the answer and the database | D16: Another Block's Staff do not find the student, every Manager does (ADR-19); students and the Admin have no desk. | E16: Test seed (2 Blocks, 48 students, 7 back-office users); Staff signed in | F16: Passed | G16: 30/10/2026 | H16: CI (mvn verify)

Sheet F-09
A2: Feature | B2: F-09 Late check-in | R2: Passed
A3: Test requirement | B3: Late check-in (FR-ASG-05); actors: Student, Staff, Manager | R3: Failed
A4: Number of TCs | B4: =COUNTA(A12:A1000) -> 3 | R4: Pending
A5: Testing Round | B5: Passed | C5: Failed | D5: Pending | E5: N/A | R5: N/A
A6: Round 1 | B6: =COUNTIF($F10:$F998,B5) -> 3 | C6: =COUNTIF($F10:$F998,C5) -> 0 | D6: =COUNTIF($F10:$F998,D5) -> 0 | E6: =COUNTIF($F10:$F998,E5) -> 0
A7: Round 2 | B7: 0 | C7: 0 | D7: 0 | E7: 0
A8: Round 3 | B8: 0 | C8: 0 | D8: 0 | E8: 0
A10: Test Case ID | B10: Test Case Description | C10: Test Case Procedure | D10: Expected Results | E10: Pre-conditions | F10: Round 1 | G10: Test date | H10: Tester | I10: Round 2 | J10: Test date | K10: Tester | L10: Round 3 | M10: Test date | N10: Tester | O10: Note
A11: FR-ASG-05
A12: TC-F09-01 | B12: [Main] The student asks online with a reason, the day and an evidence file, up to the check-in end plus late_check_in.max_days; the Managers are told; one request per Term, also after the decision; a Manager approves at most that day. | C12: Automated (LateCheckInIT.studentAsksOnline): GET /api/late-check-ins; POST /api/late-check-ins/{id}/decision; GET /api/students/me/late-check-in; POST /api/students/me/late-check-in; check the answer and the database | D12: The student asks online with a reason, the day and an evidence file, up to the check-in end plus late_check_in.max_days; the Managers are told; one request per Term, also after the decision; a Manager approves at most that day. | E12: Test seed (2 Blocks, 48 students, 7 back-office users); Student signed in | F12: Passed | G12: 30/10/2026 | H12: CI (mvn verify)
A13: TC-F09-02 | B13: [Main] Staff record the request with evidence; the Block Manager approves a deadline, after which the desk lets the student check in even though the Term's window is closed. | C13: Automated (LateCheckInIT.approvedLateCheckIn): GET /api/late-check-ins; POST /api/late-check-ins; POST /api/late-check-ins/{id}/decision; check the answer and the database | D13: Staff record the request with evidence; the Block Manager approves a deadline, after which the desk lets the student check in even though the Term's window is closed. | E13: Test seed (2 Blocks, 48 students, 7 back-office users); Staff signed in | F13: Passed | G13: 30/10/2026 | H13: CI (mvn verify)
A14: TC-F09-03 | B14: [Rule] A rejection needs a reason; every Manager sees the request (ADR-19); a student has one late check-in per Term, so the desk cannot record another after the rejection. | C14: Automated (LateCheckInIT.rejectedLateCheckIn): GET /api/late-check-ins; POST /api/late-check-ins/{id}/decision; check the answer and the database | D14: A rejection needs a reason; every Manager sees the request (ADR-19); a student has one late check-in per Term, so the desk cannot record another after the rejection. | E14: Test seed (2 Blocks, 48 students, 7 back-office users); Manager signed in | F14: Passed | G14: 30/10/2026 | H14: CI (mvn verify)

Sheet F-10
A2: Feature | B2: F-10 Next-Term requests | R2: Passed
A3: Test requirement | B3: Next-Term requests (FR-REQ-01..05); actors: Student, Staff | R3: Failed
A4: Number of TCs | B4: =COUNTA(A12:A1000) -> 6 | R4: Pending
A5: Testing Round | B5: Passed | C5: Failed | D5: Pending | E5: N/A | R5: N/A
A6: Round 1 | B6: =COUNTIF($F10:$F998,B5) -> 6 | C6: =COUNTIF($F10:$F998,C5) -> 0 | D6: =COUNTIF($F10:$F998,D5) -> 0 | E6: =COUNTIF($F10:$F998,E5) -> 0
A7: Round 2 | B7: 0 | C7: 0 | D7: 0 | E7: 0
A8: Round 3 | B8: 0 | C8: 0 | D8: 0 | E8: 0
A10: Test Case ID | B10: Test Case Description | C10: Test Case Procedure | D10: Expected Results | E10: Pre-conditions | F10: Round 1 | G10: Test date | H10: Tester | I10: Round 2 | J10: Test date | K10: Tester | L10: Round 3 | M10: Test date | N10: Tester | O10: Note
A11: FR-REQ-01..05
A12: TC-F10-01 | B12: [Main] Staff of the Block approve with a free matching Bed of the next Term: the next-Term Allocation moves there (the student still lives in their Room this Term) and the next-Term fee will be that Bed's price; no Invoice or refund is made; Staff of another Block see nothing; after the next-Term fees the Beds are fixed. | C12: Automated (RoomChangeIT.staffApprove): GET /api/room-changes; POST /api/room-changes/{id}/decision; GET /api/room-changes/{id}/matching-beds; check the answer and the database | D12: Staff of the Block approve with a free matching Bed of the next Term: the next-Term Allocation moves there (the student still lives in their Room this Term) and the next-Term fee will be that Bed's price; no Invoice or refund is made; Staff of another Block see nothing; after the next-Term fees the Beds are fixed. | E12: Test seed (2 Blocks, 48 students, 7 back-office users); Staff signed in | F12: Passed | G12: 30/10/2026 | H12: CI (mvn verify)
A13: TC-F10-02 | B13: [Main] A direct swap of next-Term Beds: the partner accepts, Staff check and approve, the two next-Term Allocations exchange Beds while both students stay where they live this Term. | C13: Automated (SwapIT.directSwap): GET /api/students/me/requests; GET /api/swap-invitations/{id}; POST /api/swap-invitations/{id}/respond; GET /api/swaps; check the answer and the database | D13: A direct swap of next-Term Beds: the partner accepts, Staff check and approve, the two next-Term Allocations exchange Beds while both students stay where they live this Term. | E13: Test seed (2 Blocks, 48 students, 7 back-office users); Student signed in | F13: Passed | G13: 30/10/2026 | H13: CI (mvn verify)
A14: TC-F10-03 | B14: [Main] The requests window in one list (room changes, swaps, Room Class changes, extensions), oldest first; a bulk decision decides each one in its own transaction and reports those it could not (a change still waiting for consent); a bulk rejection needs a reason; Staff of another Block see nothing. | C14: Automated (NextTermRequestIT.windowListAndBulk): GET /api/renewals/overview; POST /api/room-class-changes; POST /api/students/me/stay/extension; GET /api/next-term-requests; check the answer and the database | D14: The requests window in one list (room changes, swaps, Room Class changes, extensions), oldest first; a bulk decision decides each one in its own transaction and reports those it could not (a change still waiting for consent); a bulk rejection needs a reason; Staff of another Block see nothing. | E14: Test seed (2 Blocks, 48 students, 7 back-office users); Staff signed in | F14: Passed | G14: 30/10/2026 | H14: CI (mvn verify)
A15: TC-F10-04 | B15: [Rule] A Room Class change of a Room for the next Term: every other continuing resident must agree (one in the Stay's last Term is not asked); Staff cannot approve before; the furniture check reserves the missing items of the Block store; the Room's class changes for the next Term only, and the next-Term price follows it; a refusal cancels a change; Staff of another Block see nothing. | C15: Automated (NextTermRequestIT.roomClassChange): GET /api/students/me/requests; GET /api/room-class-changes/options; POST /api/room-class-changes; POST /api/room-class-changes/{id}/consent; check the answer and the database | D15: A Room Class change of a Room for the next Term: every other continuing resident must agree (one in the Stay's last Term is not asked); Staff cannot approve before; the furniture check reserves the missing items of the Block store; the Room's class changes for the next Term only, and the next-Term price follows it; a refusal cancels a change; Staff of another Block see nothing. | E15: Test seed (2 Blocks, 48 students, 7 back-office users); Student signed in | F15: Passed | G15: 30/10/2026 | H15: CI (mvn verify)
A16: TC-F10-05 | B16: [Rule] An extension in the Stay's last Term is approved at once (the Bed is kept, the Stay commits more Terms); with an overdue Invoice it waits for Staff, who decide it with a note to reject; the length is checked; the end of the stay releases the next-Term Bed at once; after the request deadline nothing can be filed. | C16: Automated (NextTermRequestIT.extensionsAndEndOfStay): GET /api/students/me/allocation; POST /api/students/me/stay/extension; POST /api/students/me/stay/end; GET /api/stay-requests; check the answer and the database | D16: An extension in the Stay's last Term is approved at once (the Bed is kept, the Stay commits more Terms); with an overdue Invoice it waits for Staff, who decide it with a note to reject; the length is checked; the end of the stay releases the next-Term Bed at once; after the request deadline nothing can be filed. | E16: Test seed (2 Blocks, 48 students, 7 back-office users); Student signed in | F16: Passed | G16: 30/10/2026 | H16: CI (mvn verify)
A17: TC-F10-06 | B17: [Exception] A rejection needs a listed reason; the student sees it; students may not decide. | C17: Automated (RoomChangeIT.staffReject): GET /api/room-changes; POST /api/room-changes/{id}/decision; check the answer and the database | D17: A rejection needs a listed reason; the student sees it; students may not decide. | E17: Test seed (2 Blocks, 48 students, 7 back-office users); Staff signed in | F17: Passed | G17: 30/10/2026 | H17: CI (mvn verify)

Sheet F-11
A2: Feature | B2: F-11 Requests window, reconciliation and next-Term fees | R2: Passed
A3: Test requirement | B3: Requests window, reconciliation and next-Term fees (FR-ASG-07, 08, FR-AUTH-08); actors: Manager, System | R3: Failed
A4: Number of TCs | B4: =COUNTA(A12:A1000) -> 6 | R4: Pending
A5: Testing Round | B5: Passed | C5: Failed | D5: Pending | E5: N/A | R5: N/A
A6: Round 1 | B6: =COUNTIF($F10:$F998,B5) -> 6 | C6: =COUNTIF($F10:$F998,C5) -> 0 | D6: =COUNTIF($F10:$F998,D5) -> 0 | E6: =COUNTIF($F10:$F998,E5) -> 0
A7: Round 2 | B7: 0 | C7: 0 | D7: 0 | E7: 0
A8: Round 3 | B8: 0 | C8: 0 | D8: 0 | E8: 0
A10: Test Case ID | B10: Test Case Description | C10: Test Case Procedure | D10: Expected Results | E10: Pre-conditions | F10: Round 1 | G10: Test date | H10: Tester | I10: Round 2 | J10: Test date | K10: Tester | L10: Round 3 | M10: Test date | N10: Tester | O10: Note
A11: FR-ASG-07, 08, FR-AUTH-08
A12: TC-F11-01 | B12: [Main] M2 opens the requests window once: a resident with Terms left keeps the Bed as continuing, one in the Stay's last Term as awaiting extension; a student not living in the Room yet and a terminated resident get none. My Room shows the next Term with its price, the students are told, Staff and Managers read the overview, and the new students' assignment of the next Term waits for the request deadline. | C12: Automated (RenewalIT.windowOpens): GET /api/inventory/rooms; GET /api/students/me/allocation; GET /api/renewals; GET /api/renewals/overview; check the answer and the database | D12: M2 opens the requests window once: a resident with Terms left keeps the Bed as continuing, one in the Stay's last Term as awaiting extension; a student not living in the Room yet and a terminated resident get none. My Room shows the next Term with its price, the students are told, Staff and Managers read the overview, and the new students' assignment of the next Term waits for the request deadline. | E12: Test seed (2 Blocks, 48 students, 7 back-office users); System (job) signed in | F12: Passed | G12: 30/10/2026 | H12: CI (mvn verify)
A13: TC-F11-02 | B13: [Main] M3 closes filing: a Bed still awaiting extension is released (the student is told in-app and by email, with the day to check out), a continuing one stays; the overview counts the ending. | C13: Automated (RenewalIT.notExtendedAtTheDeadline): GET /api/students/me/allocation; GET /api/renewals/overview; check the answer and the database | D13: M3 closes filing: a Bed still awaiting extension is released (the student is told in-app and by email, with the day to check out), a continuing one stays; the overview counts the ending. | E13: Test seed (2 Blocks, 48 students, 7 back-office users); System (job) signed in | F13: Passed | G13: 30/10/2026 | H13: CI (mvn verify)
A14: TC-F11-03 | B14: [Main] The enrolled list of the next Term: a continuing resident who graduated (group 1, the directory updated: group 4), a continuing resident missing from the list (group 2), an unknown code (group 3), another student's changed status (group 4); the template; Managers upload, the Admin reads, Staff may not; a file without a student code column is refused. | C14: Automated (ReconciliationIT.enrolledListGroups): GET /api/reconciliations; GET /api/reconciliations/template; POST /api/reconciliations; GET /api/reconciliations/{id}; check the answer and the database | D14: The enrolled list of the next Term: a continuing resident who graduated (group 1, the directory updated: group 4), a continuing resident missing from the list (group 2), an unknown code (group 3), another student's changed status (group 4); the template; Managers upload, the Admin reads, Staff may not; a file without a student code column is refused. | E14: Test seed (2 Blocks, 48 students, 7 back-office users); Manager signed in | F14: Passed | G14: 30/10/2026 | H14: CI (mvn verify)
A15: TC-F11-04 | B15: [Rule] Resolving: a note is required; "Not enrolled" releases the student's Bed for the next Term (told in the app); "Enrolled" keeps everything; an item is resolved once; then nothing blocks the next-Term fees. | C15: Automated (ReconciliationIT.resolveItems): GET /api/next-term-fees; GET /api/reconciliations; POST /api/reconciliations; GET /api/reconciliations/{id}; check the answer and the database | D15: Resolving: a note is required; "Not enrolled" releases the student's Bed for the next Term (told in the app); "Enrolled" keeps everything; an item is resolved once; then nothing blocks the next-Term fees. | E15: Test seed (2 Blocks, 48 students, 7 back-office users); Manager signed in | F15: Passed | G15: 30/10/2026 | H15: CI (mvn verify)
